[2023-04-14 16:37:59,545] {taskinstance.py:1159} INFO - Dependencies all met for <TaskInstance: af_foods.f_transform manual__2023-04-14T16:37:33.625627+00:00 [queued]>
[2023-04-14 16:37:59,550] {taskinstance.py:1159} INFO - Dependencies all met for <TaskInstance: af_foods.f_transform manual__2023-04-14T16:37:33.625627+00:00 [queued]>
[2023-04-14 16:37:59,551] {taskinstance.py:1356} INFO - 
--------------------------------------------------------------------------------
[2023-04-14 16:37:59,551] {taskinstance.py:1357} INFO - Starting attempt 1 of 2
[2023-04-14 16:37:59,551] {taskinstance.py:1358} INFO - 
--------------------------------------------------------------------------------
[2023-04-14 16:37:59,558] {taskinstance.py:1377} INFO - Executing <Task(PythonOperator): f_transform> on 2023-04-14 16:37:33.625627+00:00
[2023-04-14 16:37:59,561] {standard_task_runner.py:52} INFO - Started process 254 to run task
[2023-04-14 16:37:59,564] {standard_task_runner.py:79} INFO - Running: ['***', 'tasks', 'run', 'af_foods', 'f_transform', 'manual__2023-04-14T16:37:33.625627+00:00', '--job-id', '4', '--raw', '--subdir', 'DAGS_FOLDER/af_foods.py', '--cfg-path', '/tmp/tmp9kmzc5f0', '--error-file', '/tmp/tmp42r1palh']
[2023-04-14 16:37:59,565] {standard_task_runner.py:80} INFO - Job 4: Subtask f_transform
[2023-04-14 16:37:59,602] {task_command.py:369} INFO - Running <TaskInstance: af_foods.f_transform manual__2023-04-14T16:37:33.625627+00:00 [running]> on host df495108f1a7
[2023-04-14 16:37:59,645] {taskinstance.py:1571} INFO - Exporting the following env vars:
AIRFLOW_CTX_DAG_OWNER=me
AIRFLOW_CTX_DAG_ID=af_foods
AIRFLOW_CTX_TASK_ID=f_transform
AIRFLOW_CTX_EXECUTION_DATE=2023-04-14T16:37:33.625627+00:00
AIRFLOW_CTX_TRY_NUMBER=1
AIRFLOW_CTX_DAG_RUN_ID=manual__2023-04-14T16:37:33.625627+00:00
[2023-04-14 16:37:59,646] {taskinstance.py:1889} ERROR - Task failed with exception
Traceback (most recent call last):
  File "/opt/airflow/dags/af_foods.py", line 32, in transform
    f.transform()
  File "/opt/airflow/dags/foods.py", line 32, in transform
    foods = tranform_foods_list(cls.data)
  File "/opt/airflow/dags/etl.py", line 62, in tranform_foods_list
    return np.concatenate(foods_).tolist()
  File "<__array_function__ internals>", line 6, in concatenate
ValueError: need at least one array to concatenate

During handling of the above exception, another exception occurred:

Traceback (most recent call last):
  File "/home/airflow/.local/lib/python3.7/site-packages/airflow/operators/python.py", line 171, in execute
    return_value = self.execute_callable()
  File "/home/airflow/.local/lib/python3.7/site-packages/airflow/operators/python.py", line 189, in execute_callable
    return self.python_callable(*self.op_args, **self.op_kwargs)
  File "/opt/airflow/dags/af_foods.py", line 34, in transform
    raise Exception(f'Error during data transformation. {e}.')
Exception: Error during data transformation. need at least one array to concatenate.
[2023-04-14 16:37:59,656] {taskinstance.py:1400} INFO - Marking task as UP_FOR_RETRY. dag_id=af_foods, task_id=f_transform, execution_date=20230414T163733, start_date=20230414T163759, end_date=20230414T163759
[2023-04-14 16:37:59,662] {standard_task_runner.py:97} ERROR - Failed to execute job 4 for task f_transform (Error during data transformation. need at least one array to concatenate.; 254)
[2023-04-14 16:37:59,701] {local_task_job.py:156} INFO - Task exited with return code 1
[2023-04-14 16:37:59,731] {local_task_job.py:273} INFO - 0 downstream tasks scheduled from follow-on schedule check
